Workbook

Sheet DB_Logs
A1: Дата | B1: Время | C1: ФИО Сотрудника | D1: Тип (Приход\Уход) | E1: Tg_ID

Sheet Отчет_Декабрь
A1: ФИО Сотрудника | B1: ИТОГО | C1: 45992 | F1: 45993 | I1: 45994 | L1: 45995 | O1: 45996 | R1: 45997 | U1: 45998 | X1: 45999 | AA1: 46000 | AD1: 46001 | AG1: 46002 | AJ1: 46003 | AM1: 46004 | AP1: 46005 | AS1: 46006 | AV1: 46007 | AY1: 46008 | BB1: 46009 | BE1: 46010 | BH1: 46011 | BK1: 46012 | BN1: 46013 | BQ1: 46014 | BT1: 46015 | BW1: 46016 | BZ1: 46017 | CC1: 46018 | CF1: 46019 | CI1: 46020 | CL1: 46021 | CO1: 46022
C2: Часы | D2: Приход | E2: Уход | F2: Часы | G2: Приход | H2: Уход | I2: Часы | J2: Приход | K2: Уход | L2: Часы | M2: Приход | N2: Уход | O2: Часы | P2: Приход | Q2: Уход | R2: Часы | S2: Приход | T2: Уход | U2: Часы | V2: Приход | W2: Уход | X2: Часы | Y2: Приход | Z2: Уход | AA2: Часы | AB2: Приход | AC2: Уход | AD2: Часы | AE2: Приход | AF2: Уход | AG2: Часы | AH2: Приход | AI2: Уход | AJ2: Часы | AK2: Приход | AL2: Уход | AM2: Часы | AN2: Приход | AO2: Уход | AP2: Часы | AQ2: Приход | AR2: Уход | AS2: Часы | AT2: Приход | AU2: Уход | AV2: Часы | AW2: Приход | AX2: Уход | AY2: Часы | AZ2: Приход | BA2: Уход | BB2: Часы | BC2: Приход | BD2: Уход | BE2: Часы | BF2: Приход | BG2: Уход | BH2: Часы | BI2: Приход | BJ2: Уход | BK2: Часы | BL2: Приход | BM2: Уход | BN2: Часы | BO2: Приход | BP2: Уход | BQ2: Часы | BR2: Приход | BS2: Уход | BT2: Часы | BU2: Приход | BV2: Уход | BW2: Часы | BX2: Приход | BY2: Уход | BZ2: Часы | CA2: Приход | CB2: Уход | CC2: Часы | CD2: Приход | CE2: Уход | CF2: Часы | CG2: Приход | CH2: Уход | CI2: Часы | CJ2: Приход | CK2: Уход | CL2: Часы | CM2: Приход | CN2: Уход | CO2: Часы | CP2: Приход | CQ2: Уход
A3: Сотрудник 1 | B3: =SUMIF($2:$2, "Часы", 3:3) -> 0 | C3: =IF(OR(D3="", E3=""), "", (FLOOR(E3, "1:00") - CEILING(D3 - "00:10", "1:00") + (FLOOR(E3, "1:00") < CEILING(D3 - "00:10", "1:00"))) * 24) -> 0 | D3: =IFERROR(MINIFS(DB_Logs!$B:$B, DB_Logs!$A:$A, C$1, DB_Logs!$C:$C, $A3), "") -> 0 | E3: =IFERROR(MAXIFS(DB_Logs!$B:$B, DB_Logs!$A:$A, C$1, DB_Logs!$C:$C, $A3), "") -> 0 | F3: =IF(OR(G3="", H3=""), "", (FLOOR(H3, "1:00") - CEILING(G3 - "00:10", "1:00") + (FLOOR(H3, "1:00") < CEILING(G3 - "00:10", "1:00"))) * 24) -> 0 | G3: =IFERROR(MINIFS(DB_Logs!$B:$B, DB_Logs!$A:$A, F$1, DB_Logs!$C:$C, $A3), "") -> 0 | H3: =IFERROR(MAXIFS(DB_Logs!$B:$B, DB_Logs!$A:$A, F$1, DB_Logs!$C:$C, $A3), "") -> 0 | I3: =IF(OR(J3="", K3=""), "", (FLOOR(K3, "1:00") - CEILING(J3 - "00:10", "1:00") + (FLOOR(K3, "1:00") < CEILING(J3 - "00:10", "1:00"))) * 24) -> 0 | J3: =IFERROR(MINIFS(DB_Logs!$B:$B, DB_Logs!$A:$A, I$1, DB_Logs!$C:$C, $A3), "") -> 0 | K3: =IFERROR(MAXIFS(DB_Logs!$B:$B, DB_Logs!$A:$A, I$1, DB_Logs!$C:$C, $A3), "") -> 0 | L3: =IF(OR(M3="", N3=""), "", (FLOOR(N3, "1:00") - CEILING(M3 - "00:10", "1:00") + (FLOOR(N3, "1:00") < CEILING(M3 - "00:10", "1:00"))) * 24) -> 0 | M3: =IFERROR(MINIFS(DB_Logs!$B:$B, DB_Logs!$A:$A, L$1, DB_Logs!$C:$C, $A3), "") -> 0 | N3: =IFERROR(MAXIFS(DB_Logs!$B:$B, DB_Logs!$A:$A, L$1, DB_Logs!$C:$C, $A3), "") -> 0 | O3: =IF(OR(P3="", Q3=""), "", (FLOOR(Q3, "1:00") - CEILING(P3 - "00:10", "1:00") + (FLOOR(Q3, "1:00") < CEILING(P3 - "00:10", "1:00"))) * 24) -> 0 | P3: =IFERROR(MINIFS(DB_Logs!$B:$B, DB_Logs!$A:$A, O$1, DB_Logs!$C:$C, $A3), "") -> 0 | Q3: =IFERROR(MAXIFS(DB_Logs!$B:$B, DB_Logs!$A:$A, O$1, DB_Logs!$C:$C, $A3), "") -> 0 | R3: =IF(OR(S3="", T3=""), "", (FLOOR(T3, "1:00") - CEILING(S3 - "00:10", "1:00") + (FLOOR(T3, "1:00") < CEILING(S3 - "00:10", "1:00"))) * 24) -> 0 | S3: =IFERROR(MINIFS(DB_Logs!$B:$B, DB_Logs!$A:$A, R$1, DB_Logs!$C:$C, $A3), "") -> 0 | T3: =IFERROR(MAXIFS(DB_Logs!$B:$B, DB_Logs!$A:$A, R$1, DB_Logs!$C:$C, $A3), "") -> 0 | U3: =IF(OR(V3="", W3=""), "", (FLOOR(W3, "1:00") - CEILING(V3 - "00:10", "1:00") + (FLOOR(W3, "1:00") < CEILING(V3 - "00:10", "1:00"))) * 24) -> 0 | V3: =IFERROR(MINIFS(DB_Logs!$B:$B, DB_Logs!$A:$A, U$1, DB_Logs!$C:$C, $A3), "") -> 0 | W3: =IFERROR(MAXIFS(DB_Logs!$B:$B, DB_Logs!$A:$A, U$1, DB_Logs!$C:$C, $A3), "") -> 0 | X3: =IF(OR(Y3="", Z3=""), "", (FLOOR(Z3, "1:00") - CEILING(Y3 - "00:10", "1:00") + (FLOOR(Z3, "1:00") < CEILING(Y3 - "00:10", "1:00"))) * 24) -> 0 | Y3: =IFERROR(MINIFS(DB_Logs!$B:$B, DB_Logs!$A:$A, X$1, DB_Logs!$C:$C, $A3), "") -> 0 | Z3: =IFERROR(MAXIFS(DB_Logs!$B:$B, DB_Logs!$A:$A, X$1, DB_Logs!$C:$C, $A3), "") -> 0 | AA3: =IF(OR(AB3="", AC3=""), "", (FLOOR(AC3, "1:00") - CEILING(AB3 - "00:10", "1:00") + (FLOOR(AC3, "1:00") < CEILING(AB3 - "00:10", "1:00"))) * 24) -> 0 | AB3: =IFERROR(MINIFS(DB_Logs!$B:$B, DB_Logs!$A:$A, AA$1, DB_Logs!$C:$C, $A3), "") -> 0 | AC3: =IFERROR(MAXIFS(DB_Logs!$B:$B, DB_Logs!$A:$A, AA$1, DB_Logs!$C:$C, $A3), "") -> 0 | AD3: =IF(OR(AE3="", AF3=""), "", (FLOOR(AF3, "1:00") - CEILING(AE3 - "00:10", "1:00") + (FLOOR(AF3, "1:00") < CEILING(AE3 - "00:10", "1:00"))) * 24) -> 0 | AE3: =IFERROR(MINIFS(DB_Logs!$B:$B, DB_Logs!$A:$A, AD$1, DB_Logs!$C:$C, $A3), "") -> 0 | AF3: =IFERROR(MAXIFS(DB_Logs!$B:$B, DB_Logs!$A:$A, AD$1, DB_Logs!$C:$C, $A3), "") -> 0 | AG3: =IF(OR(AH3="", AI3=""), "", (FLOOR(AI3, "1:00") - CEILING(AH3 - "00:10", "1:00") + (FLOOR(AI3, "1:00") < CEILING(AH3 - "00:10", "1:00"))) * 24) -> 0 | AH3: =IFERROR(MINIFS(DB_Logs!$B:$B, DB_Logs!$A:$A, AG$1, DB_Logs!$C:$C, $A3), "") -> 0 | AI3: =IFERROR(MAXIFS(DB_Logs!$B:$B, DB_Logs!$A:$A, AG$1, DB_Logs!$C:$C, $A3), "") -> 0 | AJ3: =IF(OR(AK3="", AL3=""), "", (FLOOR(AL3, "1:00") - CEILING(AK3 - "00:10", "1:00") + (FLOOR(AL3, "1:00") < CEILING(AK3 - "00:10", "1:00"))) * 24) -> 0 | AK3: =IFERROR(MINIFS(DB_Logs!$B:$B, DB_Logs!$A:$A, AJ$1, DB_Logs!$C:$C, $A3), "") -> 0 | AL3: =IFERROR(MAXIFS(DB_Logs!$B:$B, DB_Logs!$A:$A, AJ$1, DB_Logs!$C:$C, $A3), "") -> 0 | AM3: =IF(OR(AN3="", AO3=""), "", (FLOOR(AO3, "1:00") - CEILING(AN3 - "00:10", "1:00") + (FLOOR(AO3, "1:00") < CEILING(AN3 - "00:10", "1:00"))) * 24) -> 0 | AN3: =IFERROR(MINIFS(DB_Logs!$B:$B, DB_Logs!$A:$A, AM$1, DB_Logs!$C:$C, $A3), "") -> 0 | AO3: =IFERROR(MAXIFS(DB_Logs!$B:$B, DB_Logs!$A:$A, AM$1, DB_Logs!$C:$C, $A3), "") -> 0 | AP3: =IF(OR(AQ3="", AR3=""), "", (FLOOR(AR3, "1:00") - CEILING(AQ3 - "00:10", "1:00") + (FLOOR(AR3, "1:00") < CEILING(AQ3 - "00:10", "1:00"))) * 24) -> 0 | AQ3: =IFERROR(MINIFS(DB_Logs!$B:$B, DB_Logs!$A:$A, AP$1, DB_Logs!$C:$C, $A3), "") -> 0 | AR3: =IFERROR(MAXIFS(DB_Logs!$B:$B, DB_Logs!$A:$A, AP$1, DB_Logs!$C:$C, $A3), "") -> 0 | AS3: =IF(OR(AT3="", AU3=""), "", (FLOOR(AU3, "1:00") - CEILING(AT3 - "00:10", "1:00") + (FLOOR(AU3, "1:00") < CEILING(AT3 - "00:10", "1:00"))) * 24) -> 0 | AT3: =IFERROR(MINIFS(DB_Logs!$B:$B, DB_Logs!$A:$A, AS$1, DB_Logs!$C:$C, $A3), "") -> 0 | AU3: =IFERROR(MAXIFS(DB_Logs!$B:$B, DB_Logs!$A:$A, AS$1, DB_Logs!$C:$C, $A3), "") -> 0 | AV3: =IF(OR(AW3="", AX3=""), "", (FLOOR(AX3, "1:00") - CEILING(AW3 - "00:10", "1:00") + (FLOOR(AX3, "1:00") < CEILING(AW3 - "00:10", "1:00"))) * 24) -> 0 | AW3: =IFERROR(MINIFS(DB_Logs!$B:$B, DB_Logs!$A:$A, AV$1, DB_Logs!$C:$C, $A3), "") -> 0 | AX3: =IFERROR(MAXIFS(DB_Logs!$B:$B, DB_Logs!$A:$A, AV$1, DB_Logs!$C:$C, $A3), "") -> 0 | AY3: =IF(OR(AZ3="", BA3=""), "", (FLOOR(BA3, "1:00") - CEILING(AZ3 - "00:10", "1:00") + (FLOOR(BA3, "1:00") < CEILING(AZ3 - "00:10", "1:00"))) * 24) -> 0 | AZ3: =IFERROR(MINIFS(DB_Logs!$B:$B, DB_Logs!$A:$A, AY$1, DB_Logs!$C:$C, $A3), "") -> 0 | BA3: =IFERROR(MAXIFS(DB_Logs!$B:$B, DB_Logs!$A:$A, AY$1, DB_Logs!$C:$C, $A3), "") -> 0 | BB3: =IF(OR(BC3="", BD3=""), "", (FLOOR(BD3, "1:00") - CEILING(BC3 - "00:10", "1:00") + (FLOOR(BD3, "1:00") < CEILING(BC3 - "00:10", "1:00"))) * 24) -> 0 | BC3: =IFERROR(MINIFS(DB_Logs!$B:$B, DB_Logs!$A:$A, BB$1, DB_Logs!$C:$C, $A3), "") -> 0 | BD3: =IFERROR(MAXIFS(DB_Logs!$B:$B, DB_Logs!$A:$A, BB$1, DB_Logs!$C:$C, $A3), "") -> 0 | BE3: =IF(OR(BF3="", BG3=""), "", (FLOOR(BG3, "1:00") - CEILING(BF3 - "00:10", "1:00") + (FLOOR(BG3, "1:00") < CEILING(BF3 - "00:10", "1:00"))) * 24) -> 0 | BF3: =IFERROR(MINIFS(DB_Logs!$B:$B, DB_Logs!$A:$A, BE$1, DB_Logs!$C:$C, $A3), "") -> 0 | BG3: =IFERROR(MAXIFS(DB_Logs!$B:$B, DB_Logs!$A:$A, BE$1, DB_Logs!$C:$C, $A3), "") -> 0 | BH3: =IF(OR(BI3="", BJ3=""), "", (FLOOR(BJ3, "1:00") - CEILING(BI3 - "00:10", "1:00") + (FLOOR(BJ3, "1:00") < CEILING(BI3 - "00:10", "1:00"))) * 24) -> 0 | BI3: =IFERROR(MINIFS(DB_Logs!$B:$B, DB_Logs!$A:$A, BH$1, DB_Logs!$C:$C, $A3), "") -> 0 | BJ3: =IFERROR(MAXIFS(DB_Logs!$B:$B, DB_Logs!$A:$A, BH$1, DB_Logs!$C:$C, $A3), "") -> 0 | BK3: =IF(OR(BL3="", BM3=""), "", (FLOOR(BM3, "1:00") - CEILING(BL3 - "00:10", "1:00") + (FLOOR(BM3, "1:00") < CEILING(BL3 - "00:10", "1:00"))) * 24) -> 0 | BL3: =IFERROR(MINIFS(DB_Logs!$B:$B, DB_Logs!$A:$A, BK$1, DB_Logs!$C:$C, $A3), "") -> 0 | BM3: =IFERROR(MAXIFS(DB_Logs!$B:$B, DB_Logs!$A:$A, BK$1, DB_Logs!$C:$C, $A3), "") -> 0 | BN3: =IF(OR(BO3="", BP3=""), "", (FLOOR(BP3, "1:00") - CEILING(BO3 - "00:10", "1:00") + (FLOOR(BP3, "1:00") < CEILING(BO3 - "00:10", "1:00"))) * 24) -> 0 | BO3: =IFERROR(MINIFS(DB_Logs!$B:$B, DB_Logs!$A:$A, BN$1, DB_Logs!$C:$C, $A3), "") -> 0 | BP3: =IFERROR(MAXIFS(DB_Logs!$B:$B, DB_Logs!$A:$A, BN$1, DB_Logs!$C:$C, $A3), "") -> 0 | BQ3: =IF(OR(BR3="", BS3=""), "", (FLOOR(BS3, "1:00") - CEILING(BR3 - "00:10", "1:00") + (FLOOR(BS3, "1:00") < CEILING(BR3 - "00:10", "1:00"))) * 24) -> 0 | BR3: =IFERROR(MINIFS(DB_Logs!$B:$B, DB_Logs!$A:$A, BQ$1, DB_Logs!$C:$C, $A3), "") -> 0 | BS3: =IFERROR(MAXIFS(DB_Logs!$B:$B, DB_Logs!$A:$A, BQ$1, DB_Logs!$C:$C, $A3), "") -> 0 | BT3: =IF(OR(BU3="", BV3=""), "", (FLOOR(BV3, "1:00") - CEILING(BU3 - "00:10", "1:00") + (FLOOR(BV3, "1:00") < CEILING(BU3 - "00:10", "1:00"))) * 24) -> 0 | BU3: =IFERROR(MINIFS(DB_Logs!$B:$B, DB_Logs!$A:$A, BT$1, DB_Logs!$C:$C, $A3), "") -> 0 | BV3: =IFERROR(MAXIFS(DB_Logs!$B:$B, DB_Logs!$A:$A, BT$1, DB_Logs!$C:$C, $A3), "") -> 0 | BW3: =IF(OR(BX3="", BY3=""), "", (FLOOR(BY3, "1:00") - CEILING(BX3 - "00:10", "1:00") + (FLOOR(BY3, "1:00") < CEILING(BX3 - "00:10", "1:00"))) * 24) -> 0 | BX3: =IFERROR(MINIFS(DB_Logs!$B:$B, DB_Logs!$A:$A, BW$1, DB_Logs!$C:$C, $A3), "") -> 0 | BY3: =IFERROR(MAXIFS(DB_Logs!$B:$B, DB_Logs!$A:$A, BW$1, DB_Logs!$C:$C, $A3), "") -> 0 | BZ3: =IF(OR(CA3="", CB3=""), "", (FLOOR(CB3, "1:00") - CEILING(CA3 - "00:10", "1:00") + (FLOOR(CB3, "1:00") < CEILING(CA3 - "00:10", "1:00"))) * 24) -> 0 | CA3: =IFERROR(MINIFS(DB_Logs!$B:$B, DB_Logs!$A:$A, BZ$1, DB_Logs!$C:$C, $A3), "") -> 0 | CB3: =IFERROR(MAXIFS(DB_Logs!$B:$B, DB_Logs!$A:$A, BZ$1, DB_Logs!$C:$C, $A3), "") -> 0 | CC3: =IF(OR(CD3="", CE3=""), "", (FLOOR(CE3, "1:00") - CEILING(CD3 - "00:10", "1:00") + (FLOOR(CE3, "1:00") < CEILING(CD3 - "00:10", "1:00"))) * 24) -> 0 | CD3: =IFERROR(MINIFS(DB_Logs!$B:$B, DB_Logs!$A:$A, CC$1, DB_Logs!$C:$C, $A3), "") -> 0 | CE3: =IFERROR(MAXIFS(DB_Logs!$B:$B, DB_Logs!$A:$A, CC$1, DB_Logs!$C:$C, $A3), "") -> 0 | CF3: =IF(OR(CG3="", CH3=""), "", (FLOOR(CH3, "1:00") - CEILING(CG3 - "00:10", "1:00") + (FLOOR(CH3, "1:00") < CEILING(CG3 - "00:10", "1:00"))) * 24) -> 0 | CG3: =IFERROR(MINIFS(DB_Logs!$B:$B, DB_Logs!$A:$A, CF$1, DB_Logs!$C:$C, $A3), "") -> 0 | CH3: =IFERROR(MAXIFS(DB_Logs!$B:$B, DB_Logs!$A:$A, CF$1, DB_Logs!$C:$C, $A3), "") -> 0 | CI3: =IF(OR(CJ3="", CK3=""), "", (FLOOR(CK3, "1:00") - CEILING(CJ3 - "00:10", "1:00") + (FLOOR(CK3, "1:00") < CEILING(CJ3 - "00:10", "1:00"))) * 24) -> 0 | CJ3: =IFERROR(MINIFS(DB_Logs!$B:$B, DB_Logs!$A:$A, CI$1, DB_Logs!$C:$C, $A3), "") -> 0 | CK3: =IFERROR(MAXIFS(DB_Logs!$B:$B, DB_Logs!$A:$A, CI$1, DB_Logs!$C:$C, $A3), "") -> 0 | CL3: =IF(OR(CM3="", CN3=""), "", (FLOOR(CN3, "1:00") - CEILING(CM3 - "00:10", "1:00") + (FLOOR(CN3, "1:00") < CEILING(CM3 - "00:10", "1:00"))) * 24) -> 0 | CM3: =IFERROR(MINIFS(DB_Logs!$B:$B, DB_Logs!$A:$A, CL$1, DB_Logs!$C:$C, $A3), "") -> 0 | CN3: =IFERROR(MAXIFS(DB_Logs!$B:$B, DB_Logs!$A:$A, CL$1, DB_Logs!$C:$C, $A3), "") -> 0 | CO3: =IF(OR(CP3="", CQ3=""), "", (FLOOR(CQ3, "1:00") - CEILING(CP3 - "00:10", "1:00") + (FLOOR(CQ3, "1:00") < CEILING(CP3 - "00:10", "1:00"))) * 24) -> 0 | CP3: =IFERROR(MINIFS(DB_Logs!$B:$B, DB_Logs!$A:$A, CO$1, DB_Logs!$C:$C, $A3), "") -> 0 | CQ3: =IFERROR(MAXIFS(DB_Logs!$B:$B, DB_Logs!$A:$A, CO$1, DB_Logs!$C:$C, $A3), "") -> 0
A4: Сотрудник 2 | B4: =SUMIF($2:$2, "Часы", 4:4) -> 0 | C4: =IF(OR(D4="", E4=""), "", (FLOOR(E4, "1:00") - CEILING(D4 - "00:10", "1:00") + (FLOOR(E4, "1:00") < CEILING(D4 - "00:10", "1:00"))) * 24) -> 0 | D4: =IFERROR(MINIFS(DB_Logs!$B:$B, DB_Logs!$A:$A, C$1, DB_Logs!$C:$C, $A4), "") -> 0 | E4: =IFERROR(MAXIFS(DB_Logs!$B:$B, DB_Logs!$A:$A, C$1, DB_Logs!$C:$C, $A4), "") -> 0 | F4: =IF(OR(G4="", H4=""), "", (FLOOR(H4, "1:00") - CEILING(G4 - "00:10", "1:00") + (FLOOR(H4, "1:00") < CEILING(G4 - "00:10", "1:00"))) * 24) -> 0 | G4: =IFERROR(MINIFS(DB_Logs!$B:$B, DB_Logs!$A:$A, F$1, DB_Logs!$C:$C, $A4), "") -> 0 | H4: =IFERROR(MAXIFS(DB_Logs!$B:$B, DB_Logs!$A:$A, F$1, DB_Logs!$C:$C, $A4), "") -> 0 | I4: =IF(OR(J4="", K4=""), "", (FLOOR(K4, "1:00") - CEILING(J4 - "00:10", "1:00") + (FLOOR(K4, "1:00") < CEILING(J4 - "00:10", "1:00"))) * 24) -> 0 | J4: =IFERROR(MINIFS(DB_Logs!$B:$B, DB_Logs!$A:$A, I$1, DB_Logs!$C:$C, $A4), "") -> 0 | K4: =IFERROR(MAXIFS(DB_Logs!$B:$B, DB_Logs!$A:$A, I$1, DB_Logs!$C:$C, $A4), "") -> 0 | L4: =IF(OR(M4="", N4=""), "", (FLOOR(N4, "1:00") - CEILING(M4 - "00:10", "1:00") + (FLOOR(N4, "1:00") < CEILING(M4 - "00:10", "1:00"))) * 24) -> 0 | M4: =IFERROR(MINIFS(DB_Logs!$B:$B, DB_Logs!$A:$A, L$1, DB_Logs!$C:$C, $A4), "") -> 0 | N4: =IFERROR(MAXIFS(DB_Logs!$B:$B, DB_Logs!$A:$A, L$1, DB_Logs!$C:$C, $A4), "") -> 0 | O4: =IF(OR(P4="", Q4=""), "", (FLOOR(Q4, "1:00") - CEILING(P4 - "00:10", "1:00") + (FLOOR(Q4, "1:00") < CEILING(P4 - "00:10", "1:00"))) * 24) -> 0 | P4: =IFERROR(MINIFS(DB_Logs!$B:$B, DB_Logs!$A:$A, O$1, DB_Logs!$C:$C, $A4), "") -> 0 | Q4: =IFERROR(MAXIFS(DB_Logs!$B:$B, DB_Logs!$A:$A, O$1, DB_Logs!$C:$C, $A4), "") -> 0 | R4: =IF(OR(S4="", T4=""), "", (FLOOR(T4, "1:00") - CEILING(S4 - "00:10", "1:00") + (FLOOR(T4, "1:00") < CEILING(S4 - "00:10", "1:00"))) * 24) -> 0 | S4: =IFERROR(MINIFS(DB_Logs!$B:$B, DB_Logs!$A:$A, R$1, DB_Logs!$C:$C, $A4), "") -> 0 | T4: =IFERROR(MAXIFS(DB_Logs!$B:$B, DB_Logs!$A:$A, R$1, DB_Logs!$C:$C, $A4), "") -> 0 | U4: =IF(OR(V4="", W4=""), "", (FLOOR(W4, "1:00") - CEILING(V4 - "00:10", "1:00") + (FLOOR(W4, "1:00") < CEILING(V4 - "00:10", "1:00"))) * 24) -> 0 | V4: =IFERROR(MINIFS(DB_Logs!$B:$B, DB_Logs!$A:$A, U$1, DB_Logs!$C:$C, $A4), "") -> 0 | W4: =IFERROR(MAXIFS(DB_Logs!$B:$B, DB_Logs!$A:$A, U$1, DB_Logs!$C:$C, $A4), "") -> 0 | X4: =IF(OR(Y4="", Z4=""), "", (FLOOR(Z4, "1:00") - CEILING(Y4 - "00:10", "1:00") + (FLOOR(Z4, "1:00") < CEILING(Y4 - "00:10", "1:00"))) * 24) -> 0 | Y4: =IFERROR(MINIFS(DB_Logs!$B:$B, DB_Logs!$A:$A, X$1, DB_Logs!$C:$C, $A4), "") -> 0 | Z4: =IFERROR(MAXIFS(DB_Logs!$B:$B, DB_Logs!$A:$A, X$1, DB_Logs!$C:$C, $A4), "") -> 0 | AA4: =IF(OR(AB4="", AC4=""), "", (FLOOR(AC4, "1:00") - CEILING(AB4 - "00:10", "1:00") + (FLOOR(AC4, "1:00") < CEILING(AB4 - "00:10", "1:00"))) * 24) -> 0 | AB4: =IFERROR(MINIFS(DB_Logs!$B:$B, DB_Logs!$A:$A, AA$1, DB_Logs!$C:$C, $A4), "") -> 0 | AC4: =IFERROR(MAXIFS(DB_Logs!$B:$B, DB_Logs!$A:$A, AA$1, DB_Logs!$C:$C, $A4), "") -> 0 | AD4: =IF(OR(AE4="", AF4=""), "", (FLOOR(AF4, "1:00") - CEILING(AE4 - "00:10", "1:00") + (FLOOR(AF4, "1:00") < CEILING(AE4 - "00:10", "1:00"))) * 24) -> 0 | AE4: =IFERROR(MINIFS(DB_Logs!$B:$B, DB_Logs!$A:$A, AD$1, DB_Logs!$C:$C, $A4), "") -> 0 | AF4: =IFERROR(MAXIFS(DB_Logs!$B:$B, DB_Logs!$A:$A, AD$1, DB_Logs!$C:$C, $A4), "") -> 0 | AG4: =IF(OR(AH4="", AI4=""), "", (FLOOR(AI4, "1:00") - CEILING(AH4 - "00:10", "1:00") + (FLOOR(AI4, "1:00") < CEILING(AH4 - "00:10", "1:00"))) * 24) -> 0 | AH4: =IFERROR(MINIFS(DB_Logs!$B:$B, DB_Logs!$A:$A, AG$1, DB_Logs!$C:$C, $A4), "") -> 0 | AI4: =IFERROR(MAXIFS(DB_Logs!$B:$B, DB_Logs!$A:$A, AG$1, DB_Logs!$C:$C, $A4), "") -> 0 | AJ4: =IF(OR(AK4="", AL4=""), "", (FLOOR(AL4, "1:00") - CEILING(AK4 - "00:10", "1:00") + (FLOOR(AL4, "1:00") < CEILING(AK4 - "00:10", "1:00"))) * 24) -> 0 | AK4: =IFERROR(MINIFS(DB_Logs!$B:$B, DB_Logs!$A:$A, AJ$1, DB_Logs!$C:$C, $A4), "") -> 0 | AL4: =IFERROR(MAXIFS(DB_Logs!$B:$B, DB_Logs!$A:$A, AJ$1, DB_Logs!$C:$C, $A4), "") -> 0 | AM4: =IF(OR(AN4="", AO4=""), "", (FLOOR(AO4, "1:00") - CEILING(AN4 - "00:10", "1:00") + (FLOOR(AO4, "1:00") < CEILING(AN4 - "00:10", "1:00"))) * 24) -> 0 | AN4: =IFERROR(MINIFS(DB_Logs!$B:$B, DB_Logs!$A:$A, AM$1, DB_Logs!$C:$C, $A4), "") -> 0 | AO4: =IFERROR(MAXIFS(DB_Logs!$B:$B, DB_Logs!$A:$A, AM$1, DB_Logs!$C:$C, $A4), "") -> 0 | AP4: =IF(OR(AQ4="", AR4=""), "", (FLOOR(AR4, "1:00") - CEILING(AQ4 - "00:10", "1:00") + (FLOOR(AR4, "1:00") < CEILING(AQ4 - "00:10", "1:00"))) * 24) -> 0 | AQ4: =IFERROR(MINIFS(DB_Logs!$B:$B, DB_Logs!$A:$A, AP$1, DB_Logs!$C:$C, $A4), "") -> 0 | AR4: =IFERROR(MAXIFS(DB_Logs!$B:$B, DB_Logs!$A:$A, AP$1, DB_Logs!$C:$C, $A4), "") -> 0 | AS4: =IF(OR(AT4="", AU4=""), "", (FLOOR(AU4, "1:00") - CEILING(AT4 - "00:10", "1:00") + (FLOOR(AU4, "1:00") < CEILING(AT4 - "00:10", "1:00"))) * 24) -> 0 | AT4: =IFERROR(MINIFS(DB_Logs!$B:$B, DB_Logs!$A:$A, AS$1, DB_Logs!$C:$C, $A4), "") -> 0 | AU4: =IFERROR(MAXIFS(DB_Logs!$B:$B, DB_Logs!$A:$A, AS$1, DB_Logs!$C:$C, $A4), "") -> 0 | AV4: =IF(OR(AW4="", AX4=""), "", (FLOOR(AX4, "1:00") - CEILING(AW4 - "00:10", "1:00") + (FLOOR(AX4, "1:00") < CEILING(AW4 - "00:10", "1:00"))) * 24) -> 0 | AW4: =IFERROR(MINIFS(DB_Logs!$B:$B, DB_Logs!$A:$A, AV$1, DB_Logs!$C:$C, $A4), "") -> 0 | AX4: =IFERROR(MAXIFS(DB_Logs!$B:$B, DB_Logs!$A:$A, AV$1, DB_Logs!$C:$C, $A4), "") -> 0 | AY4: =IF(OR(AZ4="", BA4=""), "", (FLOOR(BA4, "1:00") - CEILING(AZ4 - "00:10", "1:00") + (FLOOR(BA4, "1:00") < CEILING(AZ4 - "00:10", "1:00"))) * 24) -> 0 | AZ4: =IFERROR(MINIFS(DB_Logs!$B:$B, DB_Logs!$A:$A, AY$1, DB_Logs!$C:$C, $A4), "") -> 0 | BA4: =IFERROR(MAXIFS(DB_Logs!$B:$B, DB_Logs!$A:$A, AY$1, DB_Logs!$C:$C, $A4), "") -> 0 | BB4: =IF(OR(BC4="", BD4=""), "", (FLOOR(BD4, "1:00") - CEILING(BC4 - "00:10", "1:00") + (FLOOR(BD4, "1:00") < CEILING(BC4 - "00:10", "1:00"))) * 24) -> 0 | BC4: =IFERROR(MINIFS(DB_Logs!$B:$B, DB_Logs!$A:$A, BB$1, DB_Logs!$C:$C, $A4), "") -> 0 | BD4: =IFERROR(MAXIFS(DB_Logs!$B:$B, DB_Logs!$A:$A, BB$1, DB_Logs!$C:$C, $A4), "") -> 0 | BE4: =IF(OR(BF4="", BG4=""), "", (FLOOR(BG4, "1:00") - CEILING(BF4 - "00:10", "1:00") + (FLOOR(BG4, "1:00") < CEILING(BF4 - "00:10", "1:00"))) * 24) -> 0 | BF4: =IFERROR(MINIFS(DB_Logs!$B:$B, DB_Logs!$A:$A, BE$1, DB_Logs!$C:$C, $A4), "") -> 0 | BG4: =IFERROR(MAXIFS(DB_Logs!$B:$B, DB_Logs!$A:$A, BE$1, DB_Logs!$C:$C, $A4), "") -> 0 | BH4: =IF(OR(BI4="", BJ4=""), "", (FLOOR(BJ4, "1:00") - CEILING(BI4 - "00:10", "1:00") + (FLOOR(BJ4, "1:00") < CEILING(BI4 - "00:10", "1:00"))) * 24) -> 0 | BI4: =IFERROR(MINIFS(DB_Logs!$B:$B, DB_Logs!$A:$A, BH$1, DB_Logs!$C:$C, $A4), "") -> 0 | BJ4: =IFERROR(MAXIFS(DB_Logs!$B:$B, DB_Logs!$A:$A, BH$1, DB_Logs!$C:$C, $A4), "") -> 0 | BK4: =IF(OR(BL4="", BM4=""), "", (FLOOR(BM4, "1:00") - CEILING(BL4 - "00:10", "1:00") + (FLOOR(BM4, "1:00") < CEILING(BL4 - "00:10", "1:00"))) * 24) -> 0 | BL4: =IFERROR(MINIFS(DB_Logs!$B:$B, DB_Logs!$A:$A, BK$1, DB_Logs!$C:$C, $A4), "") -> 0 | BM4: =IFERROR(MAXIFS(DB_Logs!$B:$B, DB_Logs!$A:$A, BK$1, DB_Logs!$C:$C, $A4), "") -> 0 | BN4: =IF(OR(BO4="", BP4=""), "", (FLOOR(BP4, "1:00") - CEILING(BO4 - "00:10", "1:00") + (FLOOR(BP4, "1:00") < CEILING(BO4 - "00:10", "1:00"))) * 24) -> 0 | BO4: =IFERROR(MINIFS(DB_Logs!$B:$B, DB_Logs!$A:$A, BN$1, DB_Logs!$C:$C, $A4), "") -> 0 | BP4: =IFERROR(MAXIFS(DB_Logs!$B:$B, DB_Logs!$A:$A, BN$1, DB_Logs!$C:$C, $A4), "") -> 0 | BQ4: =IF(OR(BR4="", BS4=""), "", (FLOOR(BS4, "1:00") - CEILING(BR4 - "00:10", "1:00") + (FLOOR(BS4, "1:00") < CEILING(BR4 - "00:10", "1:00"))) * 24) -> 0 | BR4: =IFERROR(MINIFS(DB_Logs!$B:$B, DB_Logs!$A:$A, BQ$1, DB_Logs!$C:$C, $A4), "") -> 0 | BS4: =IFERROR(MAXIFS(DB_Logs!$B:$B, DB_Logs!$A:$A, BQ$1, DB_Logs!$C:$C, $A4), "") -> 0 | BT4: =IF(OR(BU4="", BV4=""), "", (FLOOR(BV4, "1:00") - CEILING(BU4 - "00:10", "1:00") + (FLOOR(BV4, "1:00") < CEILING(BU4 - "00:10", "1:00"))) * 24) -> 0 | BU4: =IFERROR(MINIFS(DB_Logs!$B:$B, DB_Logs!$A:$A, BT$1, DB_Logs!$C:$C, $A4), "") -> 0 | BV4: =IFERROR(MAXIFS(DB_Logs!$B:$B, DB_Logs!$A:$A, BT$1, DB_Logs!$C:$C, $A4), "") -> 0 | BW4: =IF(OR(BX4="", BY4=""), "", (FLOOR(BY4, "1:00") - CEILING(BX4 - "00:10", "1:00") + (FLOOR(BY4, "1:00") < CEILING(BX4 - "00:10", "1:00"))) * 24) -> 0 | BX4: =IFERROR(MINIFS(DB_Logs!$B:$B, DB_Logs!$A:$A, BW$1, DB_Logs!$C:$C, $A4), "") -> 0 | BY4: =IFERROR(MAXIFS(DB_Logs!$B:$B, DB_Logs!$A:$A, BW$1, DB_Logs!$C:$C, $A4), "") -> 0 | BZ4: =IF(OR(CA4="", CB4=""), "", (FLOOR(CB4, "1:00") - CEILING(CA4 - "00:10", "1:00") + (FLOOR(CB4, "1:00") < CEILING(CA4 - "00:10", "1:00"))) * 24) -> 0 | CA4: =IFERROR(MINIFS(DB_Logs!$B:$B, DB_Logs!$A:$A, BZ$1, DB_Logs!$C:$C, $A4), "") -> 0 | CB4: =IFERROR(MAXIFS(DB_Logs!$B:$B, DB_Logs!$A:$A, BZ$1, DB_Logs!$C:$C, $A4), "") -> 0 | CC4: =IF(OR(CD4="", CE4=""), "", (FLOOR(CE4, "1:00") - CEILING(CD4 - "00:10", "1:00") + (FLOOR(CE4, "1:00") < CEILING(CD4 - "00:10", "1:00"))) * 24) -> 0 | CD4: =IFERROR(MINIFS(DB_Logs!$B:$B, DB_Logs!$A:$A, CC$1, DB_Logs!$C:$C, $A4), "") -> 0 | CE4: =IFERROR(MAXIFS(DB_Logs!$B:$B, DB_Logs!$A:$A, CC$1, DB_Logs!$C:$C, $A4), "") -> 0 | CF4: =IF(OR(CG4="", CH4=""), "", (FLOOR(CH4, "1:00") - CEILING(CG4 - "00:10", "1:00") + (FLOOR(CH4, "1:00") < CEILING(CG4 - "00:10", "1:00"))) * 24) -> 0 | CG4: =IFERROR(MINIFS(DB_Logs!$B:$B, DB_Logs!$A:$A, CF$1, DB_Logs!$C:$C, $A4), "") -> 0 | CH4: =IFERROR(MAXIFS(DB_Logs!$B:$B, DB_Logs!$A:$A, CF$1, DB_Logs!$C:$C, $A4), "") -> 0 | CI4: =IF(OR(CJ4="", CK4=""), "", (FLOOR(CK4, "1:00") - CEILING(CJ4 - "00:10", "1:00") + (FLOOR(CK4, "1:00") < CEILING(CJ4 - "00:10", "1:00"))) * 24) -> 0 | CJ4: =IFERROR(MINIFS(DB_Logs!$B:$B, DB_Logs!$A:$A, CI$1, DB_Logs!$C:$C, $A4), "") -> 0 | CK4: =IFERROR(MAXIFS(DB_Logs!$B:$B, DB_Logs!$A:$A, CI$1, DB_Logs!$C:$C, $A4), "") -> 0 | CL4: =IF(OR(CM4="", CN4=""), "", (FLOOR(CN4, "1:00") - CEILING(CM4 - "00:10", "1:00") + (FLOOR(CN4, "1:00") < CEILING(CM4 - "00:10", "1:00"))) * 24) -> 0 | CM4: =IFERROR(MINIFS(DB_Logs!$B:$B, DB_Logs!$A:$A, CL$1, DB_Logs!$C:$C, $A4), "") -> 0 | CN4: =IFERROR(MAXIFS(DB_Logs!$B:$B, DB_Logs!$A:$A, CL$1, DB_Logs!$C:$C, $A4), "") -> 0 | CO4: =IF(OR(CP4="", CQ4=""), "", (FLOOR(CQ4, "1:00") - CEILING(CP4 - "00:10", "1:00") + (FLOOR(CQ4, "1:00") < CEILING(CP4 - "00:10", "1:00"))) * 24) -> 0 | CP4: =IFERROR(MINIFS(DB_Logs!$B:$B, DB_Logs!$A:$A, CO$1, DB_Logs!$C:$C, $A4), "") -> 0 | CQ4: =IFERROR(MAXIFS(DB_Logs!$B:$B, DB_Logs!$A:$A, CO$1, DB_Logs!$C:$C, $A4), "") -> 0
A5: Сотрудник 3 | B5: =SUMIF($2:$2, "Часы", 5:5) -> 0 | C5: =IF(OR(D5="", E5=""), "", (FLOOR(E5, "1:00") - CEILING(D5 - "00:10", "1:00") + (FLOOR(E5, "1:00") < CEILING(D5 - "00:10", "1:00"))) * 24) -> 0 | D5: =IFERROR(MINIFS(DB_Logs!$B:$B, DB_Logs!$A:$A, C$1, DB_Logs!$C:$C, $A5), "") -> 0 | E5: =IFERROR(MAXIFS(DB_Logs!$B:$B, DB_Logs!$A:$A, C$1, DB_Logs!$C:$C, $A5), "") -> 0 | F5: =IF(OR(G5="", H5=""), "", (FLOOR(H5, "1:00") - CEILING(G5 - "00:10", "1:00") + (FLOOR(H5, "1:00") < CEILING(G5 - "00:10", "1:00"))) * 24) -> 0 | G5: =IFERROR(MINIFS(DB_Logs!$B:$B, DB_Logs!$A:$A, F$1, DB_Logs!$C:$C, $A5), "") -> 0 | H5: =IFERROR(MAXIFS(DB_Logs!$B:$B, DB_Logs!$A:$A, F$1, DB_Logs!$C:$C, $A5), "") -> 0 | I5: =IF(OR(J5="", K5=""), "", (FLOOR(K5, "1:00") - CEILING(J5 - "00:10", "1:00") + (FLOOR(K5, "1:00") < CEILING(J5 - "00:10", "1:00"))) * 24) -> 0 | J5: =IFERROR(MINIFS(DB_Logs!$B:$B, DB_Logs!$A:$A, I$1, DB_Logs!$C:$C, $A5), "") -> 0 | K5: =IFERROR(MAXIFS(DB_Logs!$B:$B, DB_Logs!$A:$A, I$1, DB_Logs!$C:$C, $A5), "") -> 0 | L5: =IF(OR(M5="", N5=""), "", (FLOOR(N5, "1:00") - CEILING(M5 - "00:10", "1:00") + (FLOOR(N5, "1:00") < CEILING(M5 - "00:10", "1:00"))) * 24) -> 0 | M5: =IFERROR(MINIFS(DB_Logs!$B:$B, DB_Logs!$A:$A, L$1, DB_Logs!$C:$C, $A5), "") -> 0 | N5: =IFERROR(MAXIFS(DB_Logs!$B:$B, DB_Logs!$A:$A, L$1, DB_Logs!$C:$C, $A5), "") -> 0 | O5: =IF(OR(P5="", Q5=""), "", (FLOOR(Q5, "1:00") - CEILING(P5 - "00:10", "1:00") + (FLOOR(Q5, "1:00") < CEILING(P5 - "00:10", "1:00"))) * 24) -> 0 | P5: =IFERROR(MINIFS(DB_Logs!$B:$B, DB_Logs!$A:$A, O$1, DB_Logs!$C:$C, $A5), "") -> 0 | Q5: =IFERROR(MAXIFS(DB_Logs!$B:$B, DB_Logs!$A:$A, O$1, DB_Logs!$C:$C, $A5), "") -> 0 | R5: =IF(OR(S5="", T5=""), "", (FLOOR(T5, "1:00") - CEILING(S5 - "00:10", "1:00") + (FLOOR(T5, "1:00") < CEILING(S5 - "00:10", "1:00"))) * 24) -> 0 | S5: =IFERROR(MINIFS(DB_Logs!$B:$B, DB_Logs!$A:$A, R$1, DB_Logs!$C:$C, $A5), "") -> 0 | T5: =IFERROR(MAXIFS(DB_Logs!$B:$B, DB_Logs!$A:$A, R$1, DB_Logs!$C:$C, $A5), "") -> 0 | U5: =IF(OR(V5="", W5=""), "", (FLOOR(W5, "1:00") - CEILING(V5 - "00:10", "1:00") + (FLOOR(W5, "1:00") < CEILING(V5 - "00:10", "1:00"))) * 24) -> 0 | V5: =IFERROR(MINIFS(DB_Logs!$B:$B, DB_Logs!$A:$A, U$1, DB_Logs!$C:$C, $A5), "") -> 0 | W5: =IFERROR(MAXIFS(DB_Logs!$B:$B, DB_Logs!$A:$A, U$1, DB_Logs!$C:$C, $A5), "") -> 0 | X5: =IF(OR(Y5="", Z5=""), "", (FLOOR(Z5, "1:00") - CEILING(Y5 - "00:10", "1:00") + (FLOOR(Z5, "1:00") < CEILING(Y5 - "00:10", "1:00"))) * 24) -> 0 | Y5: =IFERROR(MINIFS(DB_Logs!$B:$B, DB_Logs!$A:$A, X$1, DB_Logs!$C:$C, $A5), "") -> 0 | Z5: =IFERROR(MAXIFS(DB_Logs!$B:$B, DB_Logs!$A:$A, X$1, DB_Logs!$C:$C, $A5), "") -> 0 | AA5: =IF(OR(AB5="", AC5=""), "", (FLOOR(AC5, "1:00") - CEILING(AB5 - "00:10", "1:00") + (FLOOR(AC5, "1:00") < CEILING(AB5 - "00:10", "1:00"))) * 24) -> 0 | AB5: =IFERROR(MINIFS(DB_Logs!$B:$B, DB_Logs!$A:$A, AA$1, DB_Logs!$C:$C, $A5), "") -> 0 | AC5: =IFERROR(MAXIFS(DB_Logs!$B:$B, DB_Logs!$A:$A, AA$1, DB_Logs!$C:$C, $A5), "") -> 0 | AD5: =IF(OR(AE5="", AF5=""), "", (FLOOR(AF5, "1:00") - CEILING(AE5 - "00:10", "1:00") + (FLOOR(AF5, "1:00") < CEILING(AE5 - "00:10", "1:00"))) * 24) -> 0 | AE5: =IFERROR(MINIFS(DB_Logs!$B:$B, DB_Logs!$A:$A, AD$1, DB_Logs!$C:$C, $A5), "") -> 0 | AF5: =IFERROR(MAXIFS(DB_Logs!$B:$B, DB_Logs!$A:$A, AD$1, DB_Logs!$C:$C, $A5), "") -> 0 | AG5: =IF(OR(AH5="", AI5=""), "", (FLOOR(AI5, "1:00") - CEILING(AH5 - "00:10", "1:00") + (FLOOR(AI5, "1:00") < CEILING(AH5 - "00:10", "1:00"))) * 24) -> 0 | AH5: =IFERROR(MINIFS(DB_Logs!$B:$B, DB_Logs!$A:$A, AG$1, DB_Logs!$C:$C, $A5), "") -> 0 | AI5: =IFERROR(MAXIFS(DB_Logs!$B:$B, DB_Logs!$A:$A, AG$1, DB_Logs!$C:$C, $A5), "") -> 0 | AJ5: =IF(OR(AK5="", AL5=""), "", (FLOOR(AL5, "1:00") - CEILING(AK5 - "00:10", "1:00") + (FLOOR(AL5, "1:00") < CEILING(AK5 - "00:10", "1:00"))) * 24) -> 0 | AK5: =IFERROR(MINIFS(DB_Logs!$B:$B, DB_Logs!$A:$A, AJ$1, DB_Logs!$C:$C, $A5), "") -> 0 | AL5: =IFERROR(MAXIFS(DB_Logs!$B:$B, DB_Logs!$A:$A, AJ$1, DB_Logs!$C:$C, $A5), "") -> 0 | AM5: =IF(OR(AN5="", AO5=""), "", (FLOOR(AO5, "1:00") - CEILING(AN5 - "00:10", "1:00") + (FLOOR(AO5, "1:00") < CEILING(AN5 - "00:10", "1:00"))) * 24) -> 0 | AN5: =IFERROR(MINIFS(DB_Logs!$B:$B, DB_Logs!$A:$A, AM$1, DB_Logs!$C:$C, $A5), "") -> 0 | AO5: =IFERROR(MAXIFS(DB_Logs!$B:$B, DB_Logs!$A:$A, AM$1, DB_Logs!$C:$C, $A5), "") -> 0 | AP5: =IF(OR(AQ5="", AR5=""), "", (FLOOR(AR5, "1:00") - CEILING(AQ5 - "00:10", "1:00") + (FLOOR(AR5, "1:00") < CEILING(AQ5 - "00:10", "1:00"))) * 24) -> 0 | AQ5: =IFERROR(MINIFS(DB_Logs!$B:$B, DB_Logs!$A:$A, AP$1, DB_Logs!$C:$C, $A5), "") -> 0 | AR5: =IFERROR(MAXIFS(DB_Logs!$B:$B, DB_Logs!$A:$A, AP$1, DB_Logs!$C:$C, $A5), "") -> 0 | AS5: =IF(OR(AT5="", AU5=""), "", (FLOOR(AU5, "1:00") - CEILING(AT5 - "00:10", "1:00") + (FLOOR(AU5, "1:00") < CEILING(AT5 - "00:10", "1:00"))) * 24) -> 0 | AT5: =IFERROR(MINIFS(DB_Logs!$B:$B, DB_Logs!$A:$A, AS$1, DB_Logs!$C:$C, $A5), "") -> 0 | AU5: =IFERROR(MAXIFS(DB_Logs!$B:$B, DB_Logs!$A:$A, AS$1, DB_Logs!$C:$C, $A5), "") -> 0 | AV5: =IF(OR(AW5="", AX5=""), "", (FLOOR(AX5, "1:00") - CEILING(AW5 - "00:10", "1:00") + (FLOOR(AX5, "1:00") < CEILING(AW5 - "00:10", "1:00"))) * 24) -> 0 | AW5: =IFERROR(MINIFS(DB_Logs!$B:$B, DB_Logs!$A:$A, AV$1, DB_Logs!$C:$C, $A5), "") -> 0 | AX5: =IFERROR(MAXIFS(DB_Logs!$B:$B, DB_Logs!$A:$A, AV$1, DB_Logs!$C:$C, $A5), "") -> 0 | AY5: =IF(OR(AZ5="", BA5=""), "", (FLOOR(BA5, "1:00") - CEILING(AZ5 - "00:10", "1:00") + (FLOOR(BA5, "1:00") < CEILING(AZ5 - "00:10", "1:00"))) * 24) -> 0 | AZ5: =IFERROR(MINIFS(DB_Logs!$B:$B, DB_Logs!$A:$A, AY$1, DB_Logs!$C:$C, $A5), "") -> 0 | BA5: =IFERROR(MAXIFS(DB_Logs!$B:$B, DB_Logs!$A:$A, AY$1, DB_Logs!$C:$C, $A5), "") -> 0 | BB5: =IF(OR(BC5="", BD5=""), "", (FLOOR(BD5, "1:00") - CEILING(BC5 - "00:10", "1:00") + (FLOOR(BD5, "1:00") < CEILING(BC5 - "00:10", "1:00"))) * 24) -> 0 | BC5: =IFERROR(MINIFS(DB_Logs!$B:$B, DB_Logs!$A:$A, BB$1, DB_Logs!$C:$C, $A5), "") -> 0 | BD5: =IFERROR(MAXIFS(DB_Logs!$B:$B, DB_Logs!$A:$A, BB$1, DB_Logs!$C:$C, $A5), "") -> 0 | BE5: =IF(OR(BF5="", BG5=""), "", (FLOOR(BG5, "1:00") - CEILING(BF5 - "00:10", "1:00") + (FLOOR(BG5, "1:00") < CEILING(BF5 - "00:10", "1:00"))) * 24) -> 0 | BF5: =IFERROR(MINIFS(DB_Logs!$B:$B, DB_Logs!$A:$A, BE$1, DB_Logs!$C:$C, $A5), "") -> 0 | BG5: =IFERROR(MAXIFS(DB_Logs!$B:$B, DB_Logs!$A:$A, BE$1, DB_Logs!$C:$C, $A5), "") -> 0 | BH5: =IF(OR(BI5="", BJ5=""), "", (FLOOR(BJ5, "1:00") - CEILING(BI5 - "00:10", "1:00") + (FLOOR(BJ5, "1:00") < CEILING(BI5 - "00:10", "1:00"))) * 24) -> 0 | BI5: =IFERROR(MINIFS(DB_Logs!$B:$B, DB_Logs!$A:$A, BH$1, DB_Logs!$C:$C, $A5), "") -> 0 | BJ5: =IFERROR(MAXIFS(DB_Logs!$B:$B, DB_Logs!$A:$A, BH$1, DB_Logs!$C:$C, $A5), "") -> 0 | BK5: =IF(OR(BL5="", BM5=""), "", (FLOOR(BM5, "1:00") - CEILING(BL5 - "00:10", "1:00") + (FLOOR(BM5, "1:00") < CEILING(BL5 - "00:10", "1:00"))) * 24) -> 0 | BL5: =IFERROR(MINIFS(DB_Logs!$B:$B, DB_Logs!$A:$A, BK$1, DB_Logs!$C:$C, $A5), "") -> 0 | BM5: =IFERROR(MAXIFS(DB_Logs!$B:$B, DB_Logs!$A:$A, BK$1, DB_Logs!$C:$C, $A5), "") -> 0 | BN5: =IF(OR(BO5="", BP5=""), "", (FLOOR(BP5, "1:00") - CEILING(BO5 - "00:10", "1:00") + (FLOOR(BP5, "1:00") < CEILING(BO5 - "00:10", "1:00"))) * 24) -> 0 | BO5: =IFERROR(MINIFS(DB_Logs!$B:$B, DB_Logs!$A:$A, BN$1, DB_Logs!$C:$C, $A5), "") -> 0 | BP5: =IFERROR(MAXIFS(DB_Logs!$B:$B, DB_Logs!$A:$A, BN$1, DB_Logs!$C:$C, $A5), "") -> 0 | BQ5: =IF(OR(BR5="", BS5=""), "", (FLOOR(BS5, "1:00") - CEILING(BR5 - "00:10", "1:00") + (FLOOR(BS5, "1:00") < CEILING(BR5 - "00:10", "1:00"))) * 24) -> 0 | BR5: =IFERROR(MINIFS(DB_Logs!$B:$B, DB_Logs!$A:$A, BQ$1, DB_Logs!$C:$C, $A5), "") -> 0 | BS5: =IFERROR(MAXIFS(DB_Logs!$B:$B, DB_Logs!$A:$A, BQ$1, DB_Logs!$C:$C, $A5), "") -> 0 | BT5: =IF(OR(BU5="", BV5=""), "", (FLOOR(BV5, "1:00") - CEILING(BU5 - "00:10", "1:00") + (FLOOR(BV5, "1:00") < CEILING(BU5 - "00:10", "1:00"))) * 24) -> 0 | BU5: =IFERROR(MINIFS(DB_Logs!$B:$B, DB_Logs!$A:$A, BT$1, DB_Logs!$C:$C, $A5), "") -> 0 | BV5: =IFERROR(MAXIFS(DB_Logs!$B:$B, DB_Logs!$A:$A, BT$1, DB_Logs!$C:$C, $A5), "") -> 0 | BW5: =IF(OR(BX5="", BY5=""), "", (FLOOR(BY5, "1:00") - CEILING(BX5 - "00:10", "1:00") + (FLOOR(BY5, "1:00") < CEILING(BX5 - "00:10", "1:00"))) * 24) -> 0 | BX5: =IFERROR(MINIFS(DB_Logs!$B:$B, DB_Logs!$A:$A, BW$1, DB_Logs!$C:$C, $A5), "") -> 0 | BY5: =IFERROR(MAXIFS(DB_Logs!$B:$B, DB_Logs!$A:$A, BW$1, DB_Logs!$C:$C, $A5), "") -> 0 | BZ5: =IF(OR(CA5="", CB5=""), "", (FLOOR(CB5, "1:00") - CEILING(CA5 - "00:10", "1:00") + (FLOOR(CB5, "1:00") < CEILING(CA5 - "00:10", "1:00"))) * 24) -> 0 | CA5: =IFERROR(MINIFS(DB_Logs!$B:$B, DB_Logs!$A:$A, BZ$1, DB_Logs!$C:$C, $A5), "") -> 0 | CB5: =IFERROR(MAXIFS(DB_Logs!$B:$B, DB_Logs!$A:$A, BZ$1, DB_Logs!$C:$C, $A5), "") -> 0 | CC5: =IF(OR(CD5="", CE5=""), "", (FLOOR(CE5, "1:00") - CEILING(CD5 - "00:10", "1:00") + (FLOOR(CE5, "1:00") < CEILING(CD5 - "00:10", "1:00"))) * 24) -> 0 | CD5: =IFERROR(MINIFS(DB_Logs!$B:$B, DB_Logs!$A:$A, CC$1, DB_Logs!$C:$C, $A5), "") -> 0 | CE5: =IFERROR(MAXIFS(DB_Logs!$B:$B, DB_Logs!$A:$A, CC$1, DB_Logs!$C:$C, $A5), "") -> 0 | CF5: =IF(OR(CG5="", CH5=""), "", (FLOOR(CH5, "1:00") - CEILING(CG5 - "00:10", "1:00") + (FLOOR(CH5, "1:00") < CEILING(CG5 - "00:10", "1:00"))) * 24) -> 0 | CG5: =IFERROR(MINIFS(DB_Logs!$B:$B, DB_Logs!$A:$A, CF$1, DB_Logs!$C:$C, $A5), "") -> 0 | CH5: =IFERROR(MAXIFS(DB_Logs!$B:$B, DB_Logs!$A:$A, CF$1, DB_Logs!$C:$C, $A5), "") -> 0 | CI5: =IF(OR(CJ5="", CK5=""), "", (FLOOR(CK5, "1:00") - CEILING(CJ5 - "00:10", "1:00") + (FLOOR(CK5, "1:00") < CEILING(CJ5 - "00:10", "1:00"))) * 24) -> 0 | CJ5: =IFERROR(MINIFS(DB_Logs!$B:$B, DB_Logs!$A:$A, CI$1, DB_Logs!$C:$C, $A5), "") -> 0 | CK5: =IFERROR(MAXIFS(DB_Logs!$B:$B, DB_Logs!$A:$A, CI$1, DB_Logs!$C:$C, $A5), "") -> 0 | CL5: =IF(OR(CM5="", CN5=""), "", (FLOOR(CN5, "1:00") - CEILING(CM5 - "00:10", "1:00") + (FLOOR(CN5, "1:00") < CEILING(CM5 - "00:10", "1:00"))) * 24) -> 0 | CM5: =IFERROR(MINIFS(DB_Logs!$B:$B, DB_Logs!$A:$A, CL$1, DB_Logs!$C:$C, $A5), "") -> 0 | CN5: =IFERROR(MAXIFS(DB_Logs!$B:$B, DB_Logs!$A:$A, CL$1, DB_Logs!$C:$C, $A5), "") -> 0 | CO5: =IF(OR(CP5="", CQ5=""), "", (FLOOR(CQ5, "1:00") - CEILING(CP5 - "00:10", "1:00") + (FLOOR(CQ5, "1:00") < CEILING(CP5 - "00:10", "1:00"))) * 24) -> 0 | CP5: =IFERROR(MINIFS(DB_Logs!$B:$B, DB_Logs!$A:$A, CO$1, DB_Logs!$C:$C, $A5), "") -> 0 | CQ5: =IFERROR(MAXIFS(DB_Logs!$B:$B, DB_Logs!$A:$A, CO$1, DB_Logs!$C:$C, $A5), "") -> 0
A6: Сотрудник 4 | B6: =SUMIF($2:$2, "Часы", 6:6) -> 0 | C6: =IF(OR(D6="", E6=""), "", (FLOOR(E6, "1:00") - CEILING(D6 - "00:10", "1:00") + (FLOOR(E6, "1:00") < CEILING(D6 - "00:10", "1:00"))) * 24) -> 0 | D6: =IFERROR(MINIFS(DB_Logs!$B:$B, DB_Logs!$A:$A, C$1, DB_Logs!$C:$C, $A6), "") -> 0 | E6: =IFERROR(MAXIFS(DB_Logs!$B:$B, DB_Logs!$A:$A, C$1, DB_Logs!$C:$C, $A6), "") -> 0 | F6: =IF(OR(G6="", H6=""), "", (FLOOR(H6, "1:00") - CEILING(G6 - "00:10", "1:00") + (FLOOR(H6, "1:00") < CEILING(G6 - "00:10", "1:00"))) * 24) -> 0 | G6: =IFERROR(MINIFS(DB_Logs!$B:$B, DB_Logs!$A:$A, F$1, DB_Logs!$C:$C, $A6), "") -> 0 | H6: =IFERROR(MAXIFS(DB_Logs!$B:$B, DB_Logs!$A:$A, F$1, DB_Logs!$C:$C, $A6), "") -> 0 | I6: =IF(OR(J6="", K6=""), "", (FLOOR(K6, "1:00") - CEILING(J6 - "00:10", "1:00") + (FLOOR(K6, "1:00") < CEILING(J6 - "00:10", "1:00"))) * 24) -> 0 | J6: =IFERROR(MINIFS(DB_Logs!$B:$B, DB_Logs!$A:$A, I$1, DB_Logs!$C:$C, $A6), "") -> 0 | K6: =IFERROR(MAXIFS(DB_Logs!$B:$B, DB_Logs!$A:$A, I$1, DB_Logs!$C:$C, $A6), "") -> 0 | L6: =IF(OR(M6="", N6=""), "", (FLOOR(N6, "1:00") - CEILING(M6 - "00:10", "1:00") + (FLOOR(N6, "1:00") < CEILING(M6 - "00:10", "1:00"))) * 24) -> 0 | M6: =IFERROR(MINIFS(DB_Logs!$B:$B, DB_Logs!$A:$A, L$1, DB_Logs!$C:$C, $A6), "") -> 0 | N6: =IFERROR(MAXIFS(DB_Logs!$B:$B, DB_Logs!$A:$A, L$1, DB_Logs!$C:$C, $A6), "") -> 0 | O6: =IF(OR(P6="", Q6=""), "", (FLOOR(Q6, "1:00") - CEILING(P6 - "00:10", "1:00") + (FLOOR(Q6, "1:00") < CEILING(P6 - "00:10", "1:00"))) * 24) -> 0 | P6: =IFERROR(MINIFS(DB_Logs!$B:$B, DB_Logs!$A:$A, O$1, DB_Logs!$C:$C, $A6), "") -> 0 | Q6: =IFERROR(MAXIFS(DB_Logs!$B:$B, DB_Logs!$A:$A, O$1, DB_Logs!$C:$C, $A6), "") -> 0 | R6: =IF(OR(S6="", T6=""), "", (FLOOR(T6, "1:00") - CEILING(S6 - "00:10", "1:00") + (FLOOR(T6, "1:00") < CEILING(S6 - "00:10", "1:00"))) * 24) -> 0 | S6: =IFERROR(MINIFS(DB_Logs!$B:$B, DB_Logs!$A:$A, R$1, DB_Logs!$C:$C, $A6), "") -> 0 | T6: =IFERROR(MAXIFS(DB_Logs!$B:$B, DB_Logs!$A:$A, R$1, DB_Logs!$C:$C, $A6), "") -> 0 | U6: =IF(OR(V6="", W6=""), "", (FLOOR(W6, "1:00") - CEILING(V6 - "00:10", "1:00") + (FLOOR(W6, "1:00") < CEILING(V6 - "00:10", "1:00"))) * 24) -> 0 | V6: =IFERROR(MINIFS(DB_Logs!$B:$B, DB_Logs!$A:$A, U$1, DB_Logs!$C:$C, $A6), "") -> 0 | W6: =IFERROR(MAXIFS(DB_Logs!$B:$B, DB_Logs!$A:$A, U$1, DB_Logs!$C:$C, $A6), "") -> 0 | X6: =IF(OR(Y6="", Z6=""), "", (FLOOR(Z6, "1:00") - CEILING(Y6 - "00:10", "1:00") + (FLOOR(Z6, "1:00") < CEILING(Y6 - "00:10", "1:00"))) * 24) -> 0 | Y6: =IFERROR(MINIFS(DB_Logs!$B:$B, DB_Logs!$A:$A, X$1, DB_Logs!$C:$C, $A6), "") -> 0 | Z6: =IFERROR(MAXIFS(DB_Logs!$B:$B, DB_Logs!$A:$A, X$1, DB_Logs!$C:$C, $A6), "") -> 0 | AA6: =IF(OR(AB6="", AC6=""), "", (FLOOR(AC6, "1:00") - CEILING(AB6 - "00:10", "1:00") + (FLOOR(AC6, "1:00") < CEILING(AB6 - "00:10", "1:00"))) * 24) -> 0 | AB6: =IFERROR(MINIFS(DB_Logs!$B:$B, DB_Logs!$A:$A, AA$1, DB_Logs!$C:$C, $A6), "") -> 0 | AC6: =IFERROR(MAXIFS(DB_Logs!$B:$B, DB_Logs!$A:$A, AA$1, DB_Logs!$C:$C, $A6), "") -> 0 | AD6: =IF(OR(AE6="", AF6=""), "", (FLOOR(AF6, "1:00") - CEILING(AE6 - "00:10", "1:00") + (FLOOR(AF6, "1:00") < CEILING(AE6 - "00:10", "1:00"))) * 24) -> 0 | AE6: =IFERROR(MINIFS(DB_Logs!$B:$B, DB_Logs!$A:$A, AD$1, DB_Logs!$C:$C, $A6), "") -> 0 | AF6: =IFERROR(MAXIFS(DB_Logs!$B:$B, DB_Logs!$A:$A, AD$1, DB_Logs!$C:$C, $A6), "") -> 0 | AG6: =IF(OR(AH6="", AI6=""), "", (FLOOR(AI6, "1:00") - CEILING(AH6 - "00:10", "1:00") + (FLOOR(AI6, "1:00") < CEILING(AH6 - "00:10", "1:00"))) * 24) -> 0 | AH6: =IFERROR(MINIFS(DB_Logs!$B:$B, DB_Logs!$A:$A, AG$1, DB_Logs!$C:$C, $A6), "") -> 0 | AI6: =IFERROR(MAXIFS(DB_Logs!$B:$B, DB_Logs!$A:$A, AG$1, DB_Logs!$C:$C, $A6), "") -> 0 | AJ6: =IF(OR(AK6="", AL6=""), "", (FLOOR(AL6, "1:00") - CEILING(AK6 - "00:10", "1:00") + (FLOOR(AL6, "1:00") < CEILING(AK6 - "00:10", "1:00"))) * 24) -> 0 | AK6: =IFERROR(MINIFS(DB_Logs!$B:$B, DB_Logs!$A:$A, AJ$1, DB_Logs!$C:$C, $A6), "") -> 0 | AL6: =IFERROR(MAXIFS(DB_Logs!$B:$B, DB_Logs!$A:$A, AJ$1, DB_Logs!$C:$C, $A6), "") -> 0 | AM6: =IF(OR(AN6="", AO6=""), "", (FLOOR(AO6, "1:00") - CEILING(AN6 - "00:10", "1:00") + (FLOOR(AO6, "1:00") < CEILING(AN6 - "00:10", "1:00"))) * 24) -> 0 | AN6: =IFERROR(MINIFS(DB_Logs!$B:$B, DB_Logs!$A:$A, AM$1, DB_Logs!$C:$C, $A6), "") -> 0 | AO6: =IFERROR(MAXIFS(DB_Logs!$B:$B, DB_Logs!$A:$A, AM$1, DB_Logs!$C:$C, $A6), "") -> 0 | AP6: =IF(OR(AQ6="", AR6=""), "", (FLOOR(AR6, "1:00") - CEILING(AQ6 - "00:10", "1:00") + (FLOOR(AR6, "1:00") < CEILING(AQ6 - "00:10", "1:00"))) * 24) -> 0 | AQ6: =IFERROR(MINIFS(DB_Logs!$B:$B, DB_Logs!$A:$A, AP$1, DB_Logs!$C:$C, $A6), "") -> 0 | AR6: =IFERROR(MAXIFS(DB_Logs!$B:$B, DB_Logs!$A:$A, AP$1, DB_Logs!$C:$C, $A6), "") -> 0 | AS6: =IF(OR(AT6="", AU6=""), "", (FLOOR(AU6, "1:00") - CEILING(AT6 - "00:10", "1:00") + (FLOOR(AU6, "1:00") < CEILING(AT6 - "00:10", "1:00"))) * 24) -> 0 | AT6: =IFERROR(MINIFS(DB_Logs!$B:$B, DB_Logs!$A:$A, AS$1, DB_Logs!$C:$C, $A6), "") -> 0 | AU6: =IFERROR(MAXIFS(DB_Logs!$B:$B, DB_Logs!$A:$A, AS$1, DB_Logs!$C:$C, $A6), "") -> 0 | AV6: =IF(OR(AW6="", AX6=""), "", (FLOOR(AX6, "1:00") - CEILING(AW6 - "00:10", "1:00") + (FLOOR(AX6, "1:00") < CEILING(AW6 - "00:10", "1:00"))) * 24) -> 0 | AW6: =IFERROR(MINIFS(DB_Logs!$B:$B, DB_Logs!$A:$A, AV$1, DB_Logs!$C:$C, $A6), "") -> 0 | AX6: =IFERROR(MAXIFS(DB_Logs!$B:$B, DB_Logs!$A:$A, AV$1, DB_Logs!$C:$C, $A6), "") -> 0 | AY6: =IF(OR(AZ6="", BA6=""), "", (FLOOR(BA6, "1:00") - CEILING(AZ6 - "00:10", "1:00") + (FLOOR(BA6, "1:00") < CEILING(AZ6 - "00:10", "1:00"))) * 24) -> 0 | AZ6: =IFERROR(MINIFS(DB_Logs!$B:$B, DB_Logs!$A:$A, AY$1, DB_Logs!$C:$C, $A6), "") -> 0 | BA6: =IFERROR(MAXIFS(DB_Logs!$B:$B, DB_Logs!$A:$A, AY$1, DB_Logs!$C:$C, $A6), "") -> 0 | BB6: =IF(OR(BC6="", BD6=""), "", (FLOOR(BD6, "1:00") - CEILING(BC6 - "00:10", "1:00") + (FLOOR(BD6, "1:00") < CEILING(BC6 - "00:10", "1:00"))) * 24) -> 0 | BC6: =IFERROR(MINIFS(DB_Logs!$B:$B, DB_Logs!$A:$A, BB$1, DB_Logs!$C:$C, $A6), "") -> 0 | BD6: =IFERROR(MAXIFS(DB_Logs!$B:$B, DB_Logs!$A:$A, BB$1, DB_Logs!$C:$C, $A6), "") -> 0 | BE6: =IF(OR(BF6="", BG6=""), "", (FLOOR(BG6, "1:00") - CEILING(BF6 - "00:10", "1:00") + (FLOOR(BG6, "1:00") < CEILING(BF6 - "00:10", "1:00"))) * 24) -> 0 | BF6: =IFERROR(MINIFS(DB_Logs!$B:$B, DB_Logs!$A:$A, BE$1, DB_Logs!$C:$C, $A6), "") -> 0 | BG6: =IFERROR(MAXIFS(DB_Logs!$B:$B, DB_Logs!$A:$A, BE$1, DB_Logs!$C:$C, $A6), "") -> 0 | BH6: =IF(OR(BI6="", BJ6=""), "", (FLOOR(BJ6, "1:00") - CEILING(BI6 - "00:10", "1:00") + (FLOOR(BJ6, "1:00") < CEILING(BI6 - "00:10", "1:00"))) * 24) -> 0 | BI6: =IFERROR(MINIFS(DB_Logs!$B:$B, DB_Logs!$A:$A, BH$1, DB_Logs!$C:$C, $A6), "") -> 0 | BJ6: =IFERROR(MAXIFS(DB_Logs!$B:$B, DB_Logs!$A:$A, BH$1, DB_Logs!$C:$C, $A6), "") -> 0 | BK6: =IF(OR(BL6="", BM6=""), "", (FLOOR(BM6, "1:00") - CEILING(BL6 - "00:10", "1:00") + (FLOOR(BM6, "1:00") < CEILING(BL6 - "00:10", "1:00"))) * 24) -> 0 | BL6: =IFERROR(MINIFS(DB_Logs!$B:$B, DB_Logs!$A:$A, BK$1, DB_Logs!$C:$C, $A6), "") -> 0 | BM6: =IFERROR(MAXIFS(DB_Logs!$B:$B, DB_Logs!$A:$A, BK$1, DB_Logs!$C:$C, $A6), "") -> 0 | BN6: =IF(OR(BO6="", BP6=""), "", (FLOOR(BP6, "1:00") - CEILING(BO6 - "00:10", "1:00") + (FLOOR(BP6, "1:00") < CEILING(BO6 - "00:10", "1:00"))) * 24) -> 0 | BO6: =IFERROR(MINIFS(DB_Logs!$B:$B, DB_Logs!$A:$A, BN$1, DB_Logs!$C:$C, $A6), "") -> 0 | BP6: =IFERROR(MAXIFS(DB_Logs!$B:$B, DB_Logs!$A:$A, BN$1, DB_Logs!$C:$C, $A6), "") -> 0 | BQ6: =IF(OR(BR6="", BS6=""), "", (FLOOR(BS6, "1:00") - CEILING(BR6 - "00:10", "1:00") + (FLOOR(BS6, "1:00") < CEILING(BR6 - "00:10", "1:00"))) * 24) -> 0 | BR6: =IFERROR(MINIFS(DB_Logs!$B:$B, DB_Logs!$A:$A, BQ$1, DB_Logs!$C:$C, $A6), "") -> 0 | BS6: =IFERROR(MAXIFS(DB_Logs!$B:$B, DB_Logs!$A:$A, BQ$1, DB_Logs!$C:$C, $A6), "") -> 0 | BT6: =IF(OR(BU6="", BV6=""), "", (FLOOR(BV6, "1:00") - CEILING(BU6 - "00:10", "1:00") + (FLOOR(BV6, "1:00") < CEILING(BU6 - "00:10", "1:00"))) * 24) -> 0 | BU6: =IFERROR(MINIFS(DB_Logs!$B:$B, DB_Logs!$A:$A, BT$1, DB_Logs!$C:$C, $A6), "") -> 0 | BV6: =IFERROR(MAXIFS(DB_Logs!$B:$B, DB_Logs!$A:$A, BT$1, DB_Logs!$C:$C, $A6), "") -> 0 | BW6: =IF(OR(BX6="", BY6=""), "", (FLOOR(BY6, "1:00") - CEILING(BX6 - "00:10", "1:00") + (FLOOR(BY6, "1:00") < CEILING(BX6 - "00:10", "1:00"))) * 24) -> 0 | BX6: =IFERROR(MINIFS(DB_Logs!$B:$B, DB_Logs!$A:$A, BW$1, DB_Logs!$C:$C, $A6), "") -> 0 | BY6: =IFERROR(MAXIFS(DB_Logs!$B:$B, DB_Logs!$A:$A, BW$1, DB_Logs!$C:$C, $A6), "") -> 0 | BZ6: =IF(OR(CA6="", CB6=""), "", (FLOOR(CB6, "1:00") - CEILING(CA6 - "00:10", "1:00") + (FLOOR(CB6, "1:00") < CEILING(CA6 - "00:10", "1:00"))) * 24) -> 0 | CA6: =IFERROR(MINIFS(DB_Logs!$B:$B, DB_Logs!$A:$A, BZ$1, DB_Logs!$C:$C, $A6), "") -> 0 | CB6: =IFERROR(MAXIFS(DB_Logs!$B:$B, DB_Logs!$A:$A, BZ$1, DB_Logs!$C:$C, $A6), "") -> 0 | CC6: =IF(OR(CD6="", CE6=""), "", (FLOOR(CE6, "1:00") - CEILING(CD6 - "00:10", "1:00") + (FLOOR(CE6, "1:00") < CEILING(CD6 - "00:10", "1:00"))) * 24) -> 0 | CD6: =IFERROR(MINIFS(DB_Logs!$B:$B, DB_Logs!$A:$A, CC$1, DB_Logs!$C:$C, $A6), "") -> 0 | CE6: =IFERROR(MAXIFS(DB_Logs!$B:$B, DB_Logs!$A:$A, CC$1, DB_Logs!$C:$C, $A6), "") -> 0 | CF6: =IF(OR(CG6="", CH6=""), "", (FLOOR(CH6, "1:00") - CEILING(CG6 - "00:10", "1:00") + (FLOOR(CH6, "1:00") < CEILING(CG6 - "00:10", "1:00"))) * 24) -> 0 | CG6: =IFERROR(MINIFS(DB_Logs!$B:$B, DB_Logs!$A:$A, CF$1, DB_Logs!$C:$C, $A6), "") -> 0 | CH6: =IFERROR(MAXIFS(DB_Logs!$B:$B, DB_Logs!$A:$A, CF$1, DB_Logs!$C:$C, $A6), "") -> 0 | CI6: =IF(OR(CJ6="", CK6=""), "", (FLOOR(CK6, "1:00") - CEILING(CJ6 - "00:10", "1:00") + (FLOOR(CK6, "1:00") < CEILING(CJ6 - "00:10", "1:00"))) * 24) -> 0 | CJ6: =IFERROR(MINIFS(DB_Logs!$B:$B, DB_Logs!$A:$A, CI$1, DB_Logs!$C:$C, $A6), "") -> 0 | CK6: =IFERROR(MAXIFS(DB_Logs!$B:$B, DB_Logs!$A:$A, CI$1, DB_Logs!$C:$C, $A6), "") -> 0 | CL6: =IF(OR(CM6="", CN6=""), "", (FLOOR(CN6, "1:00") - CEILING(CM6 - "00:10", "1:00") + (FLOOR(CN6, "1:00") < CEILING(CM6 - "00:10", "1:00"))) * 24) -> 0 | CM6: =IFERROR(MINIFS(DB_Logs!$B:$B, DB_Logs!$A:$A, CL$1, DB_Logs!$C:$C, $A6), "") -> 0 | CN6: =IFERROR(MAXIFS(DB_Logs!$B:$B, DB_Logs!$A:$A, CL$1, DB_Logs!$C:$C, $A6), "") -> 0 | CO6: =IF(OR(CP6="", CQ6=""), "", (FLOOR(CQ6, "1:00") - CEILING(CP6 - "00:10", "1:00") + (FLOOR(CQ6, "1:00") < CEILING(CP6 - "00:10", "1:00"))) * 24) -> 0 | CP6: =IFERROR(MINIFS(DB_Logs!$B:$B, DB_Logs!$A:$A, CO$1, DB_Logs!$C:$C, $A6), "") -> 0 | CQ6: =IFERROR(MAXIFS(DB_Logs!$B:$B, DB_Logs!$A:$A, CO$1, DB_Logs!$C:$C, $A6), "") -> 0
A7: Сотрудник 5 | B7: =SUMIF($2:$2, "Часы", 7:7) -> 0 | C7: =IF(OR(D7="", E7=""), "", (FLOOR(E7, "1:00") - CEILING(D7 - "00:10", "1:00") + (FLOOR(E7, "1:00") < CEILING(D7 - "00:10", "1:00"))) * 24) -> 0 | D7: =IFERROR(MINIFS(DB_Logs!$B:$B, DB_Logs!$A:$A, C$1, DB_Logs!$C:$C, $A7), "") -> 0 | E7: =IFERROR(MAXIFS(DB_Logs!$B:$B, DB_Logs!$A:$A, C$1, DB_Logs!$C:$C, $A7), "") -> 0 | F7: =IF(OR(G7="", H7=""), "", (FLOOR(H7, "1:00") - CEILING(G7 - "00:10", "1:00") + (FLOOR(H7, "1:00") < CEILING(G7 - "00:10", "1:00"))) * 24) -> 0 | G7: =IFERROR(MINIFS(DB_Logs!$B:$B, DB_Logs!$A:$A, F$1, DB_Logs!$C:$C, $A7), "") -> 0 | H7: =IFERROR(MAXIFS(DB_Logs!$B:$B, DB_Logs!$A:$A, F$1, DB_Logs!$C:$C, $A7), "") -> 0 | I7: =IF(OR(J7="", K7=""), "", (FLOOR(K7, "1:00") - CEILING(J7 - "00:10", "1:00") + (FLOOR(K7, "1:00") < CEILING(J7 - "00:10", "1:00"))) * 24) -> 0 | J7: =IFERROR(MINIFS(DB_Logs!$B:$B, DB_Logs!$A:$A, I$1, DB_Logs!$C:$C, $A7), "") -> 0 | K7: =IFERROR(MAXIFS(DB_Logs!$B:$B, DB_Logs!$A:$A, I$1, DB_Logs!$C:$C, $A7), "") -> 0 | L7: =IF(OR(M7="", N7=""), "", (FLOOR(N7, "1:00") - CEILING(M7 - "00:10", "1:00") + (FLOOR(N7, "1:00") < CEILING(M7 - "00:10", "1:00"))) * 24) -> 0 | M7: =IFERROR(MINIFS(DB_Logs!$B:$B, DB_Logs!$A:$A, L$1, DB_Logs!$C:$C, $A7), "") -> 0 | N7: =IFERROR(MAXIFS(DB_Logs!$B:$B, DB_Logs!$A:$A, L$1, DB_Logs!$C:$C, $A7), "") -> 0 | O7: =IF(OR(P7="", Q7=""), "", (FLOOR(Q7, "1:00") - CEILING(P7 - "00:10", "1:00") + (FLOOR(Q7, "1:00") < CEILING(P7 - "00:10", "1:00"))) * 24) -> 0 | P7: =IFERROR(MINIFS(DB_Logs!$B:$B, DB_Logs!$A:$A, O$1, DB_Logs!$C:$C, $A7), "") -> 0 | Q7: =IFERROR(MAXIFS(DB_Logs!$B:$B, DB_Logs!$A:$A, O$1, DB_Logs!$C:$C, $A7), "") -> 0 | R7: =IF(OR(S7="", T7=""), "", (FLOOR(T7, "1:00") - CEILING(S7 - "00:10", "1:00") + (FLOOR(T7, "1:00") < CEILING(S7 - "00:10", "1:00"))) * 24) -> 0 | S7: =IFERROR(MINIFS(DB_Logs!$B:$B, DB_Logs!$A:$A, R$1, DB_Logs!$C:$C, $A7), "") -> 0 | T7: =IFERROR(MAXIFS(DB_Logs!$B:$B, DB_Logs!$A:$A, R$1, DB_Logs!$C:$C, $A7), "") -> 0 | U7: =IF(OR(V7="", W7=""), "", (FLOOR(W7, "1:00") - CEILING(V7 - "00:10", "1:00") + (FLOOR(W7, "1:00") < CEILING(V7 - "00:10", "1:00"))) * 24) -> 0 | V7: =IFERROR(MINIFS(DB_Logs!$B:$B, DB_Logs!$A:$A, U$1, DB_Logs!$C:$C, $A7), "") -> 0 | W7: =IFERROR(MAXIFS(DB_Logs!$B:$B, DB_Logs!$A:$A, U$1, DB_Logs!$C:$C, $A7), "") -> 0 | X7: =IF(OR(Y7="", Z7=""), "", (FLOOR(Z7, "1:00") - CEILING(Y7 - "00:10", "1:00") + (FLOOR(Z7, "1:00") < CEILING(Y7 - "00:10", "1:00"))) * 24) -> 0 | Y7: =IFERROR(MINIFS(DB_Logs!$B:$B, DB_Logs!$A:$A, X$1, DB_Logs!$C:$C, $A7), "") -> 0 | Z7: =IFERROR(MAXIFS(DB_Logs!$B:$B, DB_Logs!$A:$A, X$1, DB_Logs!$C:$C, $A7), "") -> 0 | AA7: =IF(OR(AB7="", AC7=""), "", (FLOOR(AC7, "1:00") - CEILING(AB7 - "00:10", "1:00") + (FLOOR(AC7, "1:00") < CEILING(AB7 - "00:10", "1:00"))) * 24) -> 0 | AB7: =IFERROR(MINIFS(DB_Logs!$B:$B, DB_Logs!$A:$A, AA$1, DB_Logs!$C:$C, $A7), "") -> 0 | AC7: =IFERROR(MAXIFS(DB_Logs!$B:$B, DB_Logs!$A:$A, AA$1, DB_Logs!$C:$C, $A7), "") -> 0 | AD7: =IF(OR(AE7="", AF7=""), "", (FLOOR(AF7, "1:00") - CEILING(AE7 - "00:10", "1:00") + (FLOOR(AF7, "1:00") < CEILING(AE7 - "00:10", "1:00"))) * 24) -> 0 | AE7: =IFERROR(MINIFS(DB_Logs!$B:$B, DB_Logs!$A:$A, AD$1, DB_Logs!$C:$C, $A7), "") -> 0 | AF7: =IFERROR(MAXIFS(DB_Logs!$B:$B, DB_Logs!$A:$A, AD$1, DB_Logs!$C:$C, $A7), "") -> 0 | AG7: =IF(OR(AH7="", AI7=""), "", (FLOOR(AI7, "1:00") - CEILING(AH7 - "00:10", "1:00") + (FLOOR(AI7, "1:00") < CEILING(AH7 - "00:10", "1:00"))) * 24) -> 0 | AH7: =IFERROR(MINIFS(DB_Logs!$B:$B, DB_Logs!$A:$A, AG$1, DB_Logs!$C:$C, $A7), "") -> 0 | AI7: =IFERROR(MAXIFS(DB_Logs!$B:$B, DB_Logs!$A:$A, AG$1, DB_Logs!$C:$C, $A7), "") -> 0 | AJ7: =IF(OR(AK7="", AL7=""), "", (FLOOR(AL7, "1:00") - CEILING(AK7 - "00:10", "1:00") + (FLOOR(AL7, "1:00") < CEILING(AK7 - "00:10", "1:00"))) * 24) -> 0 | AK7: =IFERROR(MINIFS(DB_Logs!$B:$B, DB_Logs!$A:$A, AJ$1, DB_Logs!$C:$C, $A7), "") -> 0 | AL7: =IFERROR(MAXIFS(DB_Logs!$B:$B, DB_Logs!$A:$A, AJ$1, DB_Logs!$C:$C, $A7), "") -> 0 | AM7: =IF(OR(AN7="", AO7=""), "", (FLOOR(AO7, "1:00") - CEILING(AN7 - "00:10", "1:00") + (FLOOR(AO7, "1:00") < CEILING(AN7 - "00:10", "1:00"))) * 24) -> 0 | AN7: =IFERROR(MINIFS(DB_Logs!$B:$B, DB_Logs!$A:$A, AM$1, DB_Logs!$C:$C, $A7), "") -> 0 | AO7: =IFERROR(MAXIFS(DB_Logs!$B:$B, DB_Logs!$A:$A, AM$1, DB_Logs!$C:$C, $A7), "") -> 0 | AP7: =IF(OR(AQ7="", AR7=""), "", (FLOOR(AR7, "1:00") - CEILING(AQ7 - "00:10", "1:00") + (FLOOR(AR7, "1:00") < CEILING(AQ7 - "00:10", "1:00"))) * 24) -> 0 | AQ7: =IFERROR(MINIFS(DB_Logs!$B:$B, DB_Logs!$A:$A, AP$1, DB_Logs!$C:$C, $A7), "") -> 0 | AR7: =IFERROR(MAXIFS(DB_Logs!$B:$B, DB_Logs!$A:$A, AP$1, DB_Logs!$C:$C, $A7), "") -> 0 | AS7: =IF(OR(AT7="", AU7=""), "", (FLOOR(AU7, "1:00") - CEILING(AT7 - "00:10", "1:00") + (FLOOR(AU7, "1:00") < CEILING(AT7 - "00:10", "1:00"))) * 24) -> 0 | AT7: =IFERROR(MINIFS(DB_Logs!$B:$B, DB_Logs!$A:$A, AS$1, DB_Logs!$C:$C, $A7), "") -> 0 | AU7: =IFERROR(MAXIFS(DB_Logs!$B:$B, DB_Logs!$A:$A, AS$1, DB_Logs!$C:$C, $A7), "") -> 0 | AV7: =IF(OR(AW7="", AX7=""), "", (FLOOR(AX7, "1:00") - CEILING(AW7 - "00:10", "1:00") + (FLOOR(AX7, "1:00") < CEILING(AW7 - "00:10", "1:00"))) * 24) -> 0 | AW7: =IFERROR(MINIFS(DB_Logs!$B:$B, DB_Logs!$A:$A, AV$1, DB_Logs!$C:$C, $A7), "") -> 0 | AX7: =IFERROR(MAXIFS(DB_Logs!$B:$B, DB_Logs!$A:$A, AV$1, DB_Logs!$C:$C, $A7), "") -> 0 | AY7: =IF(OR(AZ7="", BA7=""), "", (FLOOR(BA7, "1:00") - CEILING(AZ7 - "00:10", "1:00") + (FLOOR(BA7, "1:00") < CEILING(AZ7 - "00:10", "1:00"))) * 24) -> 0 | AZ7: =IFERROR(MINIFS(DB_Logs!$B:$B, DB_Logs!$A:$A, AY$1, DB_Logs!$C:$C, $A7), "") -> 0 | BA7: =IFERROR(MAXIFS(DB_Logs!$B:$B, DB_Logs!$A:$A, AY$1, DB_Logs!$C:$C, $A7), "") -> 0 | BB7: =IF(OR(BC7="", BD7=""), "", (FLOOR(BD7, "1:00") - CEILING(BC7 - "00:10", "1:00") + (FLOOR(BD7, "1:00") < CEILING(BC7 - "00:10", "1:00"))) * 24) -> 0 | BC7: =IFERROR(MINIFS(DB_Logs!$B:$B, DB_Logs!$A:$A, BB$1, DB_Logs!$C:$C, $A7), "") -> 0 | BD7: =IFERROR(MAXIFS(DB_Logs!$B:$B, DB_Logs!$A:$A, BB$1, DB_Logs!$C:$C, $A7), "") -> 0 | BE7: =IF(OR(BF7="", BG7=""), "", (FLOOR(BG7, "1:00") - CEILING(BF7 - "00:10", "1:00") + (FLOOR(BG7, "1:00") < CEILING(BF7 - "00:10", "1:00"))) * 24) -> 0 | BF7: =IFERROR(MINIFS(DB_Logs!$B:$B, DB_Logs!$A:$A, BE$1, DB_Logs!$C:$C, $A7), "") -> 0 | BG7: =IFERROR(MAXIFS(DB_Logs!$B:$B, DB_Logs!$A:$A, BE$1, DB_Logs!$C:$C, $A7), "") -> 0 | BH7: =IF(OR(BI7="", BJ7=""), "", (FLOOR(BJ7, "1:00") - CEILING(BI7 - "00:10", "1:00") + (FLOOR(BJ7, "1:00") < CEILING(BI7 - "00:10", "1:00"))) * 24) -> 0 | BI7: =IFERROR(MINIFS(DB_Logs!$B:$B, DB_Logs!$A:$A, BH$1, DB_Logs!$C:$C, $A7), "") -> 0 | BJ7: =IFERROR(MAXIFS(DB_Logs!$B:$B, DB_Logs!$A:$A, BH$1, DB_Logs!$C:$C, $A7), "") -> 0 | BK7: =IF(OR(BL7="", BM7=""), "", (FLOOR(BM7, "1:00") - CEILING(BL7 - "00:10", "1:00") + (FLOOR(BM7, "1:00") < CEILING(BL7 - "00:10", "1:00"))) * 24) -> 0 | BL7: =IFERROR(MINIFS(DB_Logs!$B:$B, DB_Logs!$A:$A, BK$1, DB_Logs!$C:$C, $A7), "") -> 0 | BM7: =IFERROR(MAXIFS(DB_Logs!$B:$B, DB_Logs!$A:$A, BK$1, DB_Logs!$C:$C, $A7), "") -> 0 | BN7: =IF(OR(BO7="", BP7=""), "", (FLOOR(BP7, "1:00") - CEILING(BO7 - "00:10", "1:00") + (FLOOR(BP7, "1:00") < CEILING(BO7 - "00:10", "1:00"))) * 24) -> 0 | BO7: =IFERROR(MINIFS(DB_Logs!$B:$B, DB_Logs!$A:$A, BN$1, DB_Logs!$C:$C, $A7), "") -> 0 | BP7: =IFERROR(MAXIFS(DB_Logs!$B:$B, DB_Logs!$A:$A, BN$1, DB_Logs!$C:$C, $A7), "") -> 0 | BQ7: =IF(OR(BR7="", BS7=""), "", (FLOOR(BS7, "1:00") - CEILING(BR7 - "00:10", "1:00") + (FLOOR(BS7, "1:00") < CEILING(BR7 - "00:10", "1:00"))) * 24) -> 0 | BR7: =IFERROR(MINIFS(DB_Logs!$B:$B, DB_Logs!$A:$A, BQ$1, DB_Logs!$C:$C, $A7), "") -> 0 | BS7: =IFERROR(MAXIFS(DB_Logs!$B:$B, DB_Logs!$A:$A, BQ$1, DB_Logs!$C:$C, $A7), "") -> 0 | BT7: =IF(OR(BU7="", BV7=""), "", (FLOOR(BV7, "1:00") - CEILING(BU7 - "00:10", "1:00") + (FLOOR(BV7, "1:00") < CEILING(BU7 - "00:10", "1:00"))) * 24) -> 0 | BU7: =IFERROR(MINIFS(DB_Logs!$B:$B, DB_Logs!$A:$A, BT$1, DB_Logs!$C:$C, $A7), "") -> 0 | BV7: =IFERROR(MAXIFS(DB_Logs!$B:$B, DB_Logs!$A:$A, BT$1, DB_Logs!$C:$C, $A7), "") -> 0 | BW7: =IF(OR(BX7="", BY7=""), "", (FLOOR(BY7, "1:00") - CEILING(BX7 - "00:10", "1:00") + (FLOOR(BY7, "1:00") < CEILING(BX7 - "00:10", "1:00"))) * 24) -> 0 | BX7: =IFERROR(MINIFS(DB_Logs!$B:$B, DB_Logs!$A:$A, BW$1, DB_Logs!$C:$C, $A7), "") -> 0 | BY7: =IFERROR(MAXIFS(DB_Logs!$B:$B, DB_Logs!$A:$A, BW$1, DB_Logs!$C:$C, $A7), "") -> 0 | BZ7: =IF(OR(CA7="", CB7=""), "", (FLOOR(CB7, "1:00") - CEILING(CA7 - "00:10", "1:00") + (FLOOR(CB7, "1:00") < CEILING(CA7 - "00:10", "1:00"))) * 24) -> 0 | CA7: =IFERROR(MINIFS(DB_Logs!$B:$B, DB_Logs!$A:$A, BZ$1, DB_Logs!$C:$C, $A7), "") -> 0 | CB7: =IFERROR(MAXIFS(DB_Logs!$B:$B, DB_Logs!$A:$A, BZ$1, DB_Logs!$C:$C, $A7), "") -> 0 | CC7: =IF(OR(CD7="", CE7=""), "", (FLOOR(CE7, "1:00") - CEILING(CD7 - "00:10", "1:00") + (FLOOR(CE7, "1:00") < CEILING(CD7 - "00:10", "1:00"))) * 24) -> 0 | CD7: =IFERROR(MINIFS(DB_Logs!$B:$B, DB_Logs!$A:$A, CC$1, DB_Logs!$C:$C, $A7), "") -> 0 | CE7: =IFERROR(MAXIFS(DB_Logs!$B:$B, DB_Logs!$A:$A, CC$1, DB_Logs!$C:$C, $A7), "") -> 0 | CF7: =IF(OR(CG7="", CH7=""), "", (FLOOR(CH7, "1:00") - CEILING(CG7 - "00:10", "1:00") + (FLOOR(CH7, "1:00") < CEILING(CG7 - "00:10", "1:00"))) * 24) -> 0 | CG7: =IFERROR(MINIFS(DB_Logs!$B:$B, DB_Logs!$A:$A, CF$1, DB_Logs!$C:$C, $A7), "") -> 0 | CH7: =IFERROR(MAXIFS(DB_Logs!$B:$B, DB_Logs!$A:$A, CF$1, DB_Logs!$C:$C, $A7), "") -> 0 | CI7: =IF(OR(CJ7="", CK7=""), "", (FLOOR(CK7, "1:00") - CEILING(CJ7 - "00:10", "1:00") + (FLOOR(CK7, "1:00") < CEILING(CJ7 - "00:10", "1:00"))) * 24) -> 0 | CJ7: =IFERROR(MINIFS(DB_Logs!$B:$B, DB_Logs!$A:$A, CI$1, DB_Logs!$C:$C, $A7), "") -> 0 | CK7: =IFERROR(MAXIFS(DB_Logs!$B:$B, DB_Logs!$A:$A, CI$1, DB_Logs!$C:$C, $A7), "") -> 0 | CL7: =IF(OR(CM7="", CN7=""), "", (FLOOR(CN7, "1:00") - CEILING(CM7 - "00:10", "1:00") + (FLOOR(CN7, "1:00") < CEILING(CM7 - "00:10", "1:00"))) * 24) -> 0 | CM7: =IFERROR(MINIFS(DB_Logs!$B:$B, DB_Logs!$A:$A, CL$1, DB_Logs!$C:$C, $A7), "") -> 0 | CN7: =IFERROR(MAXIFS(DB_Logs!$B:$B, DB_Logs!$A:$A, CL$1, DB_Logs!$C:$C, $A7), "") -> 0 | CO7: =IF(OR(CP7="", CQ7=""), "", (FLOOR(CQ7, "1:00") - CEILING(CP7 - "00:10", "1:00") + (FLOOR(CQ7, "1:00") < CEILING(CP7 - "00:10", "1:00"))) * 24) -> 0 | CP7: =IFERROR(MINIFS(DB_Logs!$B:$B, DB_Logs!$A:$A, CO$1, DB_Logs!$C:$C, $A7), "") -> 0 | CQ7: =IFERROR(MAXIFS(DB_Logs!$B:$B, DB_Logs!$A:$A, CO$1, DB_Logs!$C:$C, $A7), "") -> 0
